2025-01-12 17:34:27,877 Getting artifact
[34m[1mwandb[0m: [32m[41mERROR[0m artifacts must be specified as 'collection:alias' (Error 400: Bad Request)
Traceback (most recent call last):
  File "/opt/anaconda3/envs/udacity-mlops/lib/python3.8/site-packages/wandb/apis/normalize.py", line 25, in wrapper
    return func(*args, **kwargs)
  File "/opt/anaconda3/envs/udacity-mlops/lib/python3.8/site-packages/wandb/apis/public/api.py", line 1214, in _artifact
    artifact = wandb.Artifact._from_name(
  File "/opt/anaconda3/envs/udacity-mlops/lib/python3.8/site-packages/wandb/sdk/artifacts/artifact.py", line 262, in _from_name
    response = client.execute(
  File "/opt/anaconda3/envs/udacity-mlops/lib/python3.8/site-packages/wandb/sdk/lib/retry.py", line 212, in wrapped_fn
    return retrier(*args, **kargs)
  File "/opt/anaconda3/envs/udacity-mlops/lib/python3.8/site-packages/wandb/sdk/lib/retry.py", line 131, in __call__
    result = self._call_fn(*args, **kwargs)
  File "/opt/anaconda3/envs/udacity-mlops/lib/python3.8/site-packages/wandb/apis/public/api.py", line 72, in execute
    return self._client.execute(*args, **kwargs)
  File "/opt/anaconda3/envs/udacity-mlops/lib/python3.8/site-packages/wandb/vendor/gql-0.2.0/wandb_gql/client.py", line 52, in execute
    result = self._get_result(document, *args, **kwargs)
  File "/opt/anaconda3/envs/udacity-mlops/lib/python3.8/site-packages/wandb/vendor/gql-0.2.0/wandb_gql/client.py", line 60, in _get_result
    return self.transport.execute(document, *args, **kwargs)
  File "/opt/anaconda3/envs/udacity-mlops/lib/python3.8/site-packages/wandb/sdk/lib/gql_request.py", line 59, in execute
    request.raise_for_status()
  File "/opt/anaconda3/envs/udacity-mlops/lib/python3.8/site-packages/requests/models.py", line 1024, in raise_for_status
    raise HTTPError(http_error_msg, response=self)
requests.exceptions.HTTPError: 400 Client Error: Bad Request for url: https://api.wandb.ai/graphql

During handling of the above exception, another exception occurred:

Traceback (most recent call last):
  File "use_artifact.py", line 43, in <module>
    go(args)
  File "use_artifact.py", line 21, in go
    artifact = run.use_artifact(args.artifact_name)
  File "/opt/anaconda3/envs/udacity-mlops/lib/python3.8/site-packages/wandb/sdk/wandb_run.py", line 392, in wrapper_fn
    return func(self, *args, **kwargs)
  File "/opt/anaconda3/envs/udacity-mlops/lib/python3.8/site-packages/wandb/sdk/wandb_run.py", line 382, in wrapper
    return func(self, *args, **kwargs)
  File "/opt/anaconda3/envs/udacity-mlops/lib/python3.8/site-packages/wandb/sdk/wandb_run.py", line 3003, in use_artifact
    artifact = public_api._artifact(type=type, name=name)
  File "/opt/anaconda3/envs/udacity-mlops/lib/python3.8/site-packages/wandb/apis/normalize.py", line 35, in wrapper
    raise CommError(message, error)
wandb.errors.errors.CommError: artifacts must be specified as 'collection:alias' (Error 400: Bad Request)
Traceback (most recent call last):
  File "/opt/anaconda3/envs/udacity-mlops/lib/python3.8/site-packages/wandb/apis/normalize.py", line 25, in wrapper
    return func(*args, **kwargs)
  File "/opt/anaconda3/envs/udacity-mlops/lib/python3.8/site-packages/wandb/apis/public/api.py", line 1214, in _artifact
    artifact = wandb.Artifact._from_name(
  File "/opt/anaconda3/envs/udacity-mlops/lib/python3.8/site-packages/wandb/sdk/artifacts/artifact.py", line 262, in _from_name
    response = client.execute(
  File "/opt/anaconda3/envs/udacity-mlops/lib/python3.8/site-packages/wandb/sdk/lib/retry.py", line 212, in wrapped_fn
    return retrier(*args, **kargs)
  File "/opt/anaconda3/envs/udacity-mlops/lib/python3.8/site-packages/wandb/sdk/lib/retry.py", line 131, in __call__
    result = self._call_fn(*args, **kwargs)
  File "/opt/anaconda3/envs/udacity-mlops/lib/python3.8/site-packages/wandb/apis/public/api.py", line 72, in execute
    return self._client.execute(*args, **kwargs)
  File "/opt/anaconda3/envs/udacity-mlops/lib/python3.8/site-packages/wandb/vendor/gql-0.2.0/wandb_gql/client.py", line 52, in execute
    result = self._get_result(document, *args, **kwargs)
  File "/opt/anaconda3/envs/udacity-mlops/lib/python3.8/site-packages/wandb/vendor/gql-0.2.0/wandb_gql/client.py", line 60, in _get_result
    return self.transport.execute(document, *args, **kwargs)
  File "/opt/anaconda3/envs/udacity-mlops/lib/python3.8/site-packages/wandb/sdk/lib/gql_request.py", line 59, in execute
    request.raise_for_status()
  File "/opt/anaconda3/envs/udacity-mlops/lib/python3.8/site-packages/requests/models.py", line 1024, in raise_for_status
    raise HTTPError(http_error_msg, response=self)
requests.exceptions.HTTPError: 400 Client Error: Bad Request for url: https://api.wandb.ai/graphql

During handling of the above exception, another exception occurred:

Traceback (most recent call last):
  File "use_artifact.py", line 43, in <module>
    go(args)
  File "use_artifact.py", line 21, in go
    artifact = run.use_artifact(args.artifact_name)
  File "/opt/anaconda3/envs/udacity-mlops/lib/python3.8/site-packages/wandb/sdk/wandb_run.py", line 392, in wrapper_fn
    return func(self, *args, **kwargs)
  File "/opt/anaconda3/envs/udacity-mlops/lib/python3.8/site-packages/wandb/sdk/wandb_run.py", line 382, in wrapper
    return func(self, *args, **kwargs)
  File "/opt/anaconda3/envs/udacity-mlops/lib/python3.8/site-packages/wandb/sdk/wandb_run.py", line 3003, in use_artifact
    artifact = public_api._artifact(type=type, name=name)
  File "/opt/anaconda3/envs/udacity-mlops/lib/python3.8/site-packages/wandb/apis/normalize.py", line 35, in wrapper
    raise CommError(message, error)
wandb.errors.errors.CommError: artifacts must be specified as 'collection:alias' (Error 400: Bad Request)
