2025-01-17 10:36:45,548 Downloading artifact
[34m[1mwandb[39m[22m: [32m[41mERROR[39m[49m Unable to fetch artifact with name zzhijuan-university-of-houston/exercise_4/genres_mod.parquet:latest
Traceback (most recent call last):
  File "/opt/anaconda3/envs/mlflow-6b1d235a149327e3f9f09905ae9265c8607a47c1/lib/python3.12/site-packages/wandb/apis/normalize.py", line 41, in wrapper
    return func(*args, **kwargs)
           ^^^^^^^^^^^^^^^^^^^^^
  File "/opt/anaconda3/envs/mlflow-6b1d235a149327e3f9f09905ae9265c8607a47c1/lib/python3.12/site-packages/wandb/apis/public/api.py", line 958, in artifact
    artifact = wandb.Artifact._from_name(
               ^^^^^^^^^^^^^^^^^^^^^^^^^^
  File "/opt/anaconda3/envs/mlflow-6b1d235a149327e3f9f09905ae9265c8607a47c1/lib/python3.12/site-packages/wandb/sdk/artifacts/artifact.py", line 254, in _from_name
    raise ValueError(
ValueError: Unable to fetch artifact with name zzhijuan-university-of-houston/exercise_4/genres_mod.parquet:latest
During handling of the above exception, another exception occurred:
Traceback (most recent call last):
  File "/Users/zhijuanzhang/Documents/UdacityCourse/MLOps_P2_Reproducible_Pipeline/Exercise/lesson-2-data-exploration-and-preparation/exercises/exercise_5/solution/run.py", line 82, in <module>
    go(args)
  File "/Users/zhijuanzhang/Documents/UdacityCourse/MLOps_P2_Reproducible_Pipeline/Exercise/lesson-2-data-exploration-and-preparation/exercises/exercise_5/solution/run.py", line 19, in go
    artifact = run.use_artifact(args.input_artifact)
               ^^^^^^^^^^^^^^^^^^^^^^^^^^^^^^^^^^^^^
  File "/opt/anaconda3/envs/mlflow-6b1d235a149327e3f9f09905ae9265c8607a47c1/lib/python3.12/site-packages/wandb/sdk/wandb_run.py", line 371, in wrapper_fn
    return func(self, *args, **kwargs)
           ^^^^^^^^^^^^^^^^^^^^^^^^^^^
  File "/opt/anaconda3/envs/mlflow-6b1d235a149327e3f9f09905ae9265c8607a47c1/lib/python3.12/site-packages/wandb/sdk/wandb_run.py", line 361, in wrapper
    return func(self, *args, **kwargs)
           ^^^^^^^^^^^^^^^^^^^^^^^^^^^
  File "/opt/anaconda3/envs/mlflow-6b1d235a149327e3f9f09905ae9265c8607a47c1/lib/python3.12/site-packages/wandb/sdk/wandb_run.py", line 2783, in use_artifact
    artifact = public_api.artifact(type=type, name=name)
               ^^^^^^^^^^^^^^^^^^^^^^^^^^^^^^^^^^^^^^^^^
  File "/opt/anaconda3/envs/mlflow-6b1d235a149327e3f9f09905ae9265c8607a47c1/lib/python3.12/site-packages/wandb/apis/normalize.py", line 87, in wrapper
    raise CommError(message, err).with_traceback(sys.exc_info()[2])
  File "/opt/anaconda3/envs/mlflow-6b1d235a149327e3f9f09905ae9265c8607a47c1/lib/python3.12/site-packages/wandb/apis/normalize.py", line 41, in wrapper
    return func(*args, **kwargs)
           ^^^^^^^^^^^^^^^^^^^^^
  File "/opt/anaconda3/envs/mlflow-6b1d235a149327e3f9f09905ae9265c8607a47c1/lib/python3.12/site-packages/wandb/apis/public/api.py", line 958, in artifact
    artifact = wandb.Artifact._from_name(
               ^^^^^^^^^^^^^^^^^^^^^^^^^^
  File "/opt/anaconda3/envs/mlflow-6b1d235a149327e3f9f09905ae9265c8607a47c1/lib/python3.12/site-packages/wandb/sdk/artifacts/artifact.py", line 254, in _from_name
    raise ValueError(
wandb.errors.CommError: Unable to fetch artifact with name zzhijuan-university-of-houston/exercise_4/genres_mod.parquet:latest